<!-- Cheetah Model

    The state space is populated with joints in the order that they are
    defined in this file. The actuators also operate on joints.

    State-Space (name/joint/parameter):
        - rootx     slider      position (m)
        - rootz     slider      position (m)
        - rooty     hinge       angle (rad)
        - bthighL    hinge       angle (rad)
        - bshinL     hinge       angle (rad)
        - bfootL     hinge       angle (rad)
        - fthighL    hinge       angle (rad)
        - fshinL    hinge       angle (rad)
        - ffootL     hinge       angle (rad)
        - bthighR    hinge       angle (rad)
        - bshinR     hinge       angle (rad)
        - bfootR     hinge       angle (rad)
        - fthighR    hinge       angle (rad)
        - fshinR     hinge       angle (rad)
        - ffootR     hinge       angle (rad)

        - rootx     slider      velocity (m/s)
        - rootz     slider      velocity (m/s)
        - rooty     hinge       angular velocity (rad/s)

        - bthighL    hinge       angular velocity (rad/s)
        - bshinL     hinge       angular velocity (rad/s)
        - bfootL     hinge       angular velocity (rad/s)
        - fthighL    hinge       angular velocity (rad/s)
        - fshinL     hinge       angular velocity (rad/s)
        - ffootL     hinge       angular velocity (rad/s)
  	- bthighR    hinge       angular velocity (rad/s)
        - bshinR     hinge       angular velocity (rad/s)
        - bfootR     hinge       angular velocity (rad/s)
        - fthighR    hinge       angular velocity (rad/s)
        - fshinR     hinge       angular velocity (rad/s)
        - ffootR     hinge       angular velocity (rad/s)

    Actuators (name/actuator/parameter):
        - bthigh    hinge       torque (N m)
        - bshin     hinge       torque (N m)
        - bfoot     hinge       torque (N m)
        - fthigh    hinge       torque (N m)
        - fshin     hinge       torque (N m)
        - ffoot     hinge       torque (N m)

-->
<mujoco model="cheetah">
  <compiler angle="radian" coordinate="local" inertiafromgeom="true" settotalmass="14"/>
  <default>
    <joint armature=".1" damping=".01" limited="true" solimplimit="0 .8 .03" solreflimit=".02 1" stiffness="8"/>
    <geom conaffinity="0" condim="3" contype="1" friction=".4 .1 .1" rgba="0.8 0.6 .4 1" solimp="0.0 0.8 0.01" solref="0.02 1"/>
    <motor ctrllimited="true" ctrlrange="-1 1"/>
  </default>
  <size nstack="300000" nuser_geom="1"/>
  <option gravity="0 0 -9.81" timestep="0.01"/>
  <asset>
    <texture builtin="gradient" height="100" rgb1="1 1 1" rgb2="0 0 0" type="skybox" width="100"/>
    <texture builtin="flat" height="1278" mark="cross" markrgb="1 1 1" name="texgeom" random="0.01" rgb1="0.8 0.6 0.4" rgb2="0.8 0.6 0.4" type="cube" width="127"/>
    <texture builtin="checker" height="100" name="texplane" rgb1="0.8 0.8 0.8" rgb2="0.8 0.8 0.8" type="2d" width="100"/>
    <material name="MatPlane" reflectance="0.5" shininess="0" specular="1" texrepeat="60 60" texture="texplane"/>
    <material name="geom" texture="texgeom" texuniform="true"/>
  </asset>
  <worldbody>
    <light cutoff="100" diffuse="1 1 1" dir="-0 0 -1.3" directional="true" exponent="1" pos="0 0 1.3" specular=".1 .1 .1"/>
    <geom conaffinity="1" condim="3" material="MatPlane" name="floor" pos="0 0 0" rgba="0.8 0.9 0.8 1" size="40 40 40" type="plane"/>
    <body name="torso" pos="0 0 .7">
      <camera name="track" mode="trackcom" pos="0 -3 0.3" xyaxes="1 0 0 0 0 1"/>
      <joint armature="0" axis="1 0 0" damping="0" limited="false" name="rootx" pos="0 0 0" stiffness="0" type="slide"/>
      <joint armature="0" axis="0 0 1" damping="0" limited="false" name="rootz" pos="0 0 0" stiffness="0" type="slide"/>
      <joint armature="0" axis="0 1 0" damping="0" limited="false" name="rooty" pos="0 0 0" stiffness="0" type="hinge"/>
      <!--<geom fromto="-.5 0 0 .5 0 0" name="torso" size="0.046" type="capsule"/>-->
      <geom name="torso" size="0.6 0.2 0.05" type="box"/>
      <geom axisangle="0 1 0 .87" name="head" pos=".55 0 .15" size="0.146 .15" type="sphere"/>
      <geom axisangle="0 1 0 -.87" name="tail" pos="-.55 0 .1" size="0.046 .05" type="capsule"/>
	<geom  name="earL" pos=".55 0.07 .29" size="0.025 0.025 0.03" type="box"/>
	<geom  name="earR" pos=".55 -0.07 .29" size="0.025 0.025 0.03" type="box"/>
       <!--<site name='tip'  pos='.15 0 .11'/>-->
      <body name="bthighL" pos="-.5 0.1 0">
        <joint axis="0 1 0" damping="6" name="bthighL" pos="0 0 0" range="-.52 1.05" stiffness="240" type="hinge"/>
        <geom axisangle="0 1 0 -3.8" name="bthighL" pos=".1 0 -.13" size="0.046 .145" type="capsule"/>
        <body name="bshinL" pos=".16 0 -.25">
          <joint axis="0 1 0" damping="4.5" name="bshinL" pos="0 0 0" range="-.785 .785" stiffness="180" type="hinge"/>
          <geom axisangle="0 1 0 -2.03" name="bshinL" pos="-.14 0 -.07" rgba="0.9 0.6 0.6 1" size="0.046 .15" type="capsule"/>
          <body name="bfootL" pos="-.28 0 -.14">
            <joint axis="0 1 0" damping="3" name="bfootL" pos="0 0 0" range="-.4 .785" stiffness="120" type="hinge"/>
            <geom axisangle="0 1 0 -.27" name="bfootL" pos=".03 0 -.097" rgba="0.9 0.6 0.6 1" size="0.046 .094" type="capsule"/>
          </body>
        </body>
      </body>
      <body name="fthighL" pos=".45 0.1 0">
        <joint axis="0 1 0" damping="4.5" name="fthighL" pos="0 0 0" range="-1 .7" stiffness="180" type="hinge"/>
        <geom axisangle="0 1 0 .52" name="fthighL" pos="-.07 0 -.12" size="0.046 .133" type="capsule"/>
        <body name="fshinL" pos="-.14 0 -.24">
          <joint axis="0 1 0" damping="3" name="fshinL" pos="0 0 0" range="-1.2 .87" stiffness="120" type="hinge"/>
          <geom axisangle="0 1 0 -.6" name="fshinL" pos=".065 0 -.09" rgba="0.9 0.6 0.6 1" size="0.046 .106" type="capsule"/>
          <body name="ffootL" pos=".13 0 -.18">
            <joint axis="0 1 0" damping="1.5" name="ffootL" pos="0 0 0" range="-.5 .5" stiffness="60" type="hinge"/>
            <geom axisangle="0 1 0 -.6" name="ffootL" pos=".045 0 -.07" rgba="0.9 0.6 0.6 1" size="0.046 .07" type="capsule"/>
          </body>
        </body>
      </body>
      <body name="bthighR" pos="-.5 -0.1 0">
        <joint axis="0 1 0" damping="6" name="bthighR" pos="0 0 0" range="-.52 1.05" stiffness="240" type="hinge"/>
        <geom axisangle="0 1 0 -3.8" name="bthighR" pos=".1 0 -.13" size="0.046 .145" type="capsule" rgba="1 0 0 1" />
        <body name="bshinR" pos=".16 0 -.25">
          <joint axis="0 1 0" damping="4.5" name="bshinR" pos="0 0 0" range="-.785 .785" stiffness="180" type="hinge"/>
          <geom axisangle="0 1 0 -2.03" name="bshinR" pos="-.14 0 -.07" rgba="1 0 0 1"  size="0.046 .15" type="capsule"/>
          <body name="bfootR" pos="-.28 0 -.14">
            <joint axis="0 1 0" damping="3" name="bfootR" pos="0 0 0" range="-.4 .785" stiffness="120" type="hinge"/>
            <geom axisangle="0 1 0 -.27" name="bfootR" pos=".03 0 -.097" rgba="1 0 0 1"  size="0.046 .094" type="capsule"/>
          </body>
        </body>
      </body>
      <body name="fthighR" pos=".45 -0.1 0">
        <joint axis="0 1 0" damping="4.5" name="fthighR" pos="0 0 0" range="-1 .7" stiffness="180" type="hinge"/>
        <geom axisangle="0 1 0 .52" name="fthighR" pos="-.07 0 -.12" size="0.046 .133" type="capsule" rgba="1 0 0 1" />
        <body name="fshinR" pos="-.14 0 -.24">
          <joint axis="0 1 0" damping="3" name="fshinR" pos="0 0 0" range="-1.2 .87" stiffness="120" type="hinge"/>
          <geom axisangle="0 1 0 -.6" name="fshinR" pos=".065 0 -.09"rgba="1 0 0 1"  size="0.046 .106" type="capsule"/>
          <body name="ffootR" pos=".13 0 -.18">
            <joint axis="0 1 0" damping="1.5" name="ffootR" pos="0 0 0" range="-.5 .5" stiffness="60" type="hinge"/>
            <geom axisangle="0 1 0 -.6" name="ffootR" pos=".045 0 -.07" rgba="1 0 0 1"  size="0.046 .07" type="capsule"/>
          </body>
        </body>
      </body>
    </body>
  </worldbody>
  <actuator>
    <motor gear="120" joint="bthighL" name="bthighL"/>
    <motor gear="90" joint="bshinL" name="bshinL"/>
    <motor gear="60" joint="bfootL" name="bfootL"/>
    <motor gear="120" joint="fthighL" name="fthighL"/>
    <motor gear="60" joint="fshinL" name="fshinL"/>
    <motor gear="30" joint="ffootL" name="ffootL"/>
    <motor gear="120" joint="bthighR" name="bthighR"/>
    <motor gear="90" joint="bshinR" name="bshinR"/>
    <motor gear="60" joint="bfootR" name="bfootR"/>
    <motor gear="120" joint="fthighR" name="fthighR"/>
    <motor gear="60" joint="fshinR" name="fshinR"/>
    <motor gear="30" joint="ffootR" name="ffootR"/>
  </actuator>
</mujoco>
