<!-- Cheetah Model

    The state space is populated with joints in the order that they are
    defined in this file. The actuators also operate on joints.

    State-Space (name/joint/parameter):
        - rootx     slider      position (m)
        - rootz     slider      position (m)
        - rooty     hinge       angle (rad)
        - bthigh    hinge       angle (rad)
        - bshin     hinge       angle (rad)
        - bfoot     hinge       angle (rad)
        - fthigh    hinge       angle (rad)
        - fshin     hinge       angle (rad)
        - ffoot     hinge       angle (rad)
        - rootx     slider      velocity (m/s)
        - rootz     slider      velocity (m/s)
        - rooty     hinge       angular velocity (rad/s)
        - bthigh    hinge       angular velocity (rad/s)
        - bshin     hinge       angular velocity (rad/s)
        - bfoot     hinge       angular velocity (rad/s)
        - fthigh    hinge       angular velocity (rad/s)
        - fshin     hinge       angular velocity (rad/s)
        - ffoot     hinge       angular velocity (rad/s)

    Actuators (name/actuator/parameter):
        - bthigh    hinge       torque (N m)
        - bshin     hinge       torque (N m)
        - bfoot     hinge       torque (N m)
        - fthigh    hinge       torque (N m)
        - fshin     hinge       torque (N m)
        - ffoot     hinge       torque (N m)
	settotalmass="14"
-->
<mujoco model="cheetah">
  <compiler angle="radian" coordinate="local" inertiafromgeom="true" />
  <default>
    <joint armature=".1" damping=".01" limited="true" solimplimit="0 .8 .03" solreflimit=".02 1" stiffness="8"/>
    <geom conaffinity="0" condim="3" contype="1" friction=".4 .1 .1" rgba="0.8 0.6 .4 1" solimp="0.0 0.8 0.01" solref="0.02 1"/>
    <motor ctrllimited="true" ctrlrange="-1 1"/>
  </default>
  <size nstack="300000" nuser_geom="1"/>
  <option gravity="0 0 -9.81" timestep="0.01"/>
  <asset>
    <texture builtin="gradient" height="100" rgb1="1 1 1" rgb2="0 0 0" type="skybox" width="100"/>
    <texture builtin="flat" height="1278" mark="cross" markrgb="1 1 1" name="texgeom" random="0.01" rgb1="0.8 0.6 0.4" rgb2="0.8 0.6 0.4" type="cube" width="127"/>
    <texture builtin="checker" height="100" name="texplane" rgb1="0.8 0.8 0.8" rgb2="0.8 0.8 0.8" type="2d" width="100"/>
    <material name="MatPlane" reflectance="0.5" shininess="0" specular="1" texrepeat="60 60" texture="texplane"/>
    <material name="geom" texture="texgeom" texuniform="true"/>
  </asset>
  <worldbody>
    <light cutoff="100" diffuse="1 1 1" dir="-0 0 -1.3" directional="true" exponent="1" pos="0 0 1.3" specular=".1 .1 .1"/>
    <geom conaffinity="1" condim="3" material="MatPlane" name="floor" pos="0 0 0" rgba="0.8 0.9 0.8 1" size="40 40 40" type="plane"/>
    <body name="torso" pos="0 0 1.5">
      <camera name="track" mode="trackcom" pos="0 -5 0.3" xyaxes="1 0 0 0 0 1"/>
      <joint armature="0" axis="1 0 0" damping="0" limited="false" name="rootx" pos="0 0 0" stiffness="0" type="slide"/>
      <joint armature="0" axis="0 0 1" damping="0" limited="false" name="rootz" pos="0 0 0" stiffness="0" type="slide"/>
      <joint armature="0" axis="0 1 0" damping="0" limited="false" name="rooty" pos="0 0 0" stiffness="0" type="hinge"/>
      <geom  name="torso" size="0.5 0.046 0.2" type="box" mass='8'/>

      <geom axisangle="0 1 0 .5" name="head" pos=".65 0 .65" size="0.046 .7" type="capsule" mass='3'/>
      <!-- <site name='tip'  pos='.15 0 .11'/>-->
      <body name="bthigh" pos="-.45 0 -0.46">
        <joint axis="0 1 0" damping="6" name="bthigh" pos="0 0 0.45" range="-0.5 0.3" stiffness="240" type="hinge"/>
        <geom axisangle="0 1 0 -2.8" name="bthigh" pos="0 0 0" size="0.046 .28" type="capsule" mass='4'/>
        <body name="bshin" pos="-.13 0 -.55">
          <joint axis="0 1 0" damping="4.5" name="bshin" pos="0 0 0.30" range="-.0 2" stiffness="180" type="hinge"/>
          <geom axisangle="0 1 0 0.1" name="bshin" pos="0 0 0" rgba="0.9 0.6 0.6 1" size="0.046 .23" type="capsule" mass='2'/>
          <body name="bfoot" pos=".015 0 -.33">
            <joint axis="0 1 0" damping="3" name="bfoot" pos="-0.1 0 0.04" range="-.4 .785" stiffness="120" type="hinge"/>
            <geom axisangle="0 1 0 -.4" name="bfoot" pos=".0 0 0" rgba="0.9 0.6 0.6 1" size="0.046 .08" type="capsule" mass='0.5'/>
          </body>
        </body>
      </body>
      <body name="fthigh" pos=".38 0 -0.45">
        <joint axis="0 1 0" damping="4.5" name="fthigh" pos="0 0 0.4" range="-.5 .3" stiffness="180" type="hinge"/>
        <geom axisangle="0 1 0 .0" name="fthigh" pos="-.00 0 -.0" size="0.046 .25" type="capsule" mass='4'/>
        <body name="fshin" pos="-.0 0 -.52">
          <joint axis="0 1 0" damping="3" name="fshin" pos="0 0 0.3" range="-0 2" stiffness="120" type="hinge"/>
          <geom axisangle="0 1 0 -.0" name="fshin" pos=".0 0 .0" rgba="0.9 0.6 0.6 1" size="0.046 .23" type="capsule" mass='2'/>
          <body name="ffoot" pos=".04 0 -.3">
            <joint axis="0 1 0" damping="1.5" name="ffoot" pos="0 0 0.1" range="-.7 .0" stiffness="60" type="hinge"/>
            <geom axisangle="0 1 0 -0.4" name="ffoot" pos=".0 0 -.0" rgba="0.9 0.6 0.6 1" size="0.046 .08" type="capsule" mass='0.5'/>
          </body>
        </body>
      </body>
    </body>
  </worldbody>
  <actuator>
    <motor gear="120" joint="bthigh" name="bthigh"/>
    <motor gear="90" joint="bshin" name="bshin"/>
    <motor gear="30" joint="bfoot" name="bfoot"/>
    <motor gear="120" joint="fthigh" name="fthigh"/>
    <motor gear="60" joint="fshin" name="fshin"/>
    <motor gear="30" joint="ffoot" name="ffoot"/>
  </actuator>
</mujoco>
